Workbook

Sheet Augest 2025
E1: TEWOS TRADING PLC
A2: ISSUE No;1 | E2: Document Titel:-PAYROLL FOR THE MONTH OF AUGEST 2017 E.C/2025G.C
A3: S/N. | B3: Name of Employees | C3: Job Tittle | D3: STARTING DATE | E3: Basic Salary | F3: Number Of Working Days | G3: Per Day | H3: Monthly Pay | I3: Transport Allowance | J3: Taxabel Transport Allowance | K3: Over Time Hour | N3: perdime non taxabel | O3: Over Time Amount | P3: house allowance | Q3: Gross Salary | R3: Taxable Income | S3: Deductions | V3: Employeer pen. contribution11 % | W3: Total Deductions | X3: Net Pay
K4: Regular (1.5) | L4: Sunday (2) | M4: Holiday(2.5) | S4: IT | T4: Loan & Others Deductions | U4: Employee pen. contribution7 %
S5: =IF(R5<=2000,0,IF(R5<=4000,R5*0.15-300,IF(R5<=7000,R5*0.2-500,IF(R5<=10000,R5*0.25-850,IF(R5<=14000,R5*0.3-1350,IF(R5>=14001,R5*0.35-2050)))))) -> 0
A6: 1 | B6: Tewodros Atnafu | D6: 8\11\2022 | E6: 14569 | F6: 30 | G6: =E6/30 -> 485.63333 | H6: =E6*F6/30 -> 14569 | I6: 2200 | O6: =G6/8*1.5*K6+G6/8*L6*2+G6/8*2.5*M6 -> 0 | Q6: =H6+I6+J6+O6+P6+N6 -> 16769 | R6: =H6+J6+O6+P6 -> 14569 | S6: =IF(R6<=2000,0,IF(R6<=4000,R6*0.15-300,IF(R6<=7000,R6*0.2-500,IF(R6<=10000,R6*0.25-850,IF(R6<=14000,R6*0.3-1350,IF(R6>=14001,R6*0.35-2050)))))) -> 3049.15 | U6: =+H6*0.07 -> 1019.83 | V6: =+H6*0.11 -> 1602.59 | W6: =+S6+T6+U6 -> 4068.98 | X6: =+Q6-W6 -> 12700.02
A7: 2 | B7: Selam T\haimanote | D7: 8\11\2022 | E7: 14569 | F7: 30 | G7: =E7/30 -> 485.63333 | H7: =E7*F7/30 -> 14569 | I7: 2200 | O7: =G7/8*1.5*K7+G7/8*L7*2+G7/8*2.5*M7 -> 0 | Q7: =H7+I7+J7+O7+P7+N7 -> 16769 | R7: =H7+J7+O7+P7 -> 14569 | S7: =IF(R7<=2000,0,IF(R7<=4000,R7*0.15-300,IF(R7<=7000,R7*0.2-500,IF(R7<=10000,R7*0.25-850,IF(R7<=14000,R7*0.3-1350,IF(R7>=14001,R7*0.35-2050)))))) -> 3049.15 | U7: =+H7*0.07 -> 1019.83 | V7: =+H7*0.11 -> 1602.59 | W7: =+S7+T7+U7 -> 4068.98 | X7: =+Q7-W7 -> 12700.02
A8: 3 | B8: Samrawit Atnafu | D8: 8\11\2022 | E8: 18916 | F8: 30 | G8: =E8/30 -> 630.53333 | H8: =E8*F8/30 -> 18916 | I8: 600 | O8: =G8/8*1.5*K8+G8/8*L8*2+G8/8*2.5*M8 -> 0 | Q8: =H8+I8+J8+O8+P8+N8 -> 19516 | R8: =H8+J8+O8+P8 -> 18916 | S8: =IF(R8<=2000,0,IF(R8<=4000,R8*0.15-300,IF(R8<=7000,R8*0.2-500,IF(R8<=10000,R8*0.25-850,IF(R8<=14000,R8*0.3-1350,IF(R8>=14001,R8*0.35-2050)))))) -> 4570.6 | U8: =+H8*0.07 -> 1324.12 | V8: =+H8*0.11 -> 2080.76 | W8: =+S8+T8+U8 -> 5894.72 | X8: =+Q8-W8 -> 13621.28
A9: 4 | B9: Amanuel Beyene | D9: 8\24\2022 | E9: 18916 | F9: 30 | G9: =E9/30 -> 630.53333 | H9: =E9*F9/30 -> 18916 | I9: 600 | O9: =G9/8*1.5*K9+G9/8*L9*2+G9/8*2.5*M9 -> 0 | Q9: =H9+I9+J9+O9+P9+N9 -> 19516 | R9: =H9+J9+O9+P9 -> 18916 | S9: =IF(R9<=2000,0,IF(R9<=4000,R9*0.15-300,IF(R9<=7000,R9*0.2-500,IF(R9<=10000,R9*0.25-850,IF(R9<=14000,R9*0.3-1350,IF(R9>=14001,R9*0.35-2050)))))) -> 4570.6 | U9: =+H9*0.07 -> 1324.12 | V9: =+H9*0.11 -> 2080.76 | W9: =+S9+T9+U9 -> 5894.72 | X9: =+Q9-W9 -> 13621.28
A10: 5 | B10: Melkie Kindie | D10: 6\10\2022 | E10: 18916 | F10: 30 | G10: =E10/30 -> 630.53333 | H10: =E10*F10/30 -> 18916 | I10: 600 | O10: =G10/8*1.5*K10+G10/8*L10*2+G10/8*2.5*M10 -> 0 | Q10: =H10+I10+J10+O10+P10+N10 -> 19516 | R10: =H10+J10+O10+P10 -> 18916 | S10: =IF(R10<=2000,0,IF(R10<=4000,R10*0.15-300,IF(R10<=7000,R10*0.2-500,IF(R10<=10000,R10*0.25-850,IF(R10<=14000,R10*0.3-1350,IF(R10>=14001,R10*0.35-2050)))))) -> 4570.6 | U10: =+H10*0.07 -> 1324.12 | V10: =+H10*0.11 -> 2080.76 | W10: =+S10+T10+U10 -> 5894.72 | X10: =+Q10-W10 -> 13621.28
A11: 6 | B11: Tekalegne Defar | D11: 8\10\2023 | E11: 50425 | F11: 30 | G11: =E11/30 -> 1680.8333 | H11: =E11*F11/30 -> 50425 | I11: 600 | O11: =G11/8*1.5*K11+G11/8*L11*2+G11/8*2.5*M11 -> 0 | Q11: =H11+I11+J11+O11+P11+N11 -> 51025 | R11: =H11+J11+O11+P11 -> 50425 | S11: =IF(R11<=2000,0,IF(R11<=4000,R11*0.15-300,IF(R11<=7000,R11*0.2-500,IF(R11<=10000,R11*0.25-850,IF(R11<=14000,R11*0.3-1350,IF(R11>=14001,R11*0.35-2050)))))) -> 15598.75 | U11: =+H11*0.07 -> 3529.75 | V11: =+H11*0.11 -> 5546.75 | W11: =+S11+T11+U11 -> 19128.5 | X11: =+Q11-W11 -> 31896.5
A12: 7 | B12: Solomon Kassahun | D12: 8\10\2023 | E12: 33778.28 | F12: 30 | G12: =E12/30 -> 1125.9427 | H12: =E12*F12/30 -> 33778.28 | I12: 600 | O12: =G12/8*1.5*K12+G12/8*L12*2+G12/8*2.5*M12 -> 0 | Q12: =H12+I12+J12+O12+P12+N12 -> 34378.28 | R12: =H12+J12+O12+P12 -> 33778.28 | S12: =IF(R12<=2000,0,IF(R12<=4000,R12*0.15-300,IF(R12<=7000,R12*0.2-500,IF(R12<=10000,R12*0.25-850,IF(R12<=14000,R12*0.3-1350,IF(R12>=14001,R12*0.35-2050)))))) -> 9772.398 | U12: =+H12*0.07 -> 2364.4796 | V12: =+H12*0.11 -> 3715.6108 | W12: =+S12+T12+U12 -> 12136.878 | X12: =+Q12-W12 -> 22241.402
A13: 8 | B13: Amanuel Almayehu | D13: 8\10\2023 | E13: 13143.17 | F13: 30 | G13: =E13/30 -> 438.10567 | H13: =E13*F13/30 -> 13143.17 | I13: 600 | Q13: =H13+I13+J13+O13+P13+N13 -> 13743.17 | R13: =H13+J13+O13+P13 -> 13143.17 | S13: =IF(R13<=2000,0,IF(R13<=4000,R13*0.15-300,IF(R13<=7000,R13*0.2-500,IF(R13<=10000,R13*0.25-850,IF(R13<=14000,R13*0.3-1350,IF(R13>=14001,R13*0.35-2050)))))) -> 2592.951 | U13: =+H13*0.07 -> 920.0219 | V13: =+H13*0.11 -> 1445.7487 | W13: =+S13+T13+U13 -> 3512.9729 | X13: =+Q13-W13 -> 10230.197
A14: 9 | B14: Derbew Ayelegne | D14: 2\1\2024 | E14: 4928.1 | F14: 30 | G14: =E14/30 -> 164.27 | H14: =E14*F14/30 -> 4928.1 | I14: 600 | Q14: =H14+I14+J14+O14+P14+N14 -> 5528.1 | R14: =H14+J14+O14+P14 -> 4928.1 | S14: =IF(R14<=2000,0,IF(R14<=4000,R14*0.15-300,IF(R14<=7000,R14*0.2-500,IF(R14<=10000,R14*0.25-850,IF(R14<=14000,R14*0.3-1350,IF(R14>=14001,R14*0.35-2050)))))) -> 485.62 | U14: =+H14*0.07 -> 344.967 | V14: =+H14*0.11 -> 542.091 | W14: =+S14+T14+U14 -> 830.587 | X14: =+Q14-W14 -> 4697.513
A15: 10 | B15: Demeke Getachew | D15: 10\10\2022 | E15: 4928.1 | F15: 30 | G15: =E15/30 -> 164.27 | H15: =E15*F15/30 -> 4928.1 | I15: 600 | O15: =G15/8*1.5*K15+G15/8*L15*2+G15/8*2.5*M15 -> 0 | Q15: =H15+I15+J15+O15+P15+N15 -> 5528.1 | R15: =H15+J15+O15+P15 -> 4928.1 | S15: =IF(R15<=2000,0,IF(R15<=4000,R15*0.15-300,IF(R15<=7000,R15*0.2-500,IF(R15<=10000,R15*0.25-850,IF(R15<=14000,R15*0.3-1350,IF(R15>=14001,R15*0.35-2050)))))) -> 485.62 | U15: =+H15*0.07 -> 344.967 | V15: =+H15*0.11 -> 542.091 | W15: =+S15+T15+U15 -> 830.587 | X15: =+Q15-W15 -> 4697.513
A16: 11 | B16: Sewunet Alemu | D16: 6\10\2022 | E16: 2556.86 | F16: 30 | G16: =E16/30 -> 85.228667 | H16: =E16*F16/30 -> 2556.86 | I16: 600 | O16: =G16/8*1.5*K16+G16/8*L16*2+G16/8*2.5*M16 -> 0 | Q16: =H16+I16+J16+O16+P16+N16 -> 3156.86 | R16: =H16+J16+O16+P16 -> 2556.86 | S16: =IF(R16<=2000,0,IF(R16<=4000,R16*0.15-300,IF(R16<=7000,R16*0.2-500,IF(R16<=10000,R16*0.25-850,IF(R16<=14000,R16*0.3-1350,IF(R16>=14001,R16*0.35-2050)))))) -> 83.529 | U16: =+H16*0.07 -> 178.9802 | V16: =+H16*0.11 -> 281.2546 | W16: =+S16+T16+U16 -> 262.5092 | X16: =+Q16-W16 -> 2894.3508
A17: 12 | B17: Yordanos Demirew | D17: 7\8\2025 | E17: 5955.88 | F17: 30 | G17: =E17/30 -> 198.52933 | H17: =E17*F17/30 -> 5955.88 | I17: 600 | O17: =G17/8*1.5*K17+G17/8*L17*2+G17/8*2.5*M17 -> 0 | P17: 2000 | Q17: =H17+I17+J17+O17+P17+N17 -> 8555.88 | R17: =H17+J17+O17+P17 -> 7955.88 | S17: =IF(R17<=2000,0,IF(R17<=4000,R17*0.15-300,IF(R17<=7000,R17*0.2-500,IF(R17<=10000,R17*0.25-850,IF(R17<=14000,R17*0.3-1350,IF(R17>=14001,R17*0.35-2050)))))) -> 1138.97 | U17: =+H17*0.07 -> 416.9116 | V17: =+H17*0.11 -> 655.1468 | W17: =+S17+T17+U17 -> 1555.8816 | X17: =+Q17-W17 -> 6999.9984
A18: 13 | B18: Awoke Guade | D18: 7\8\2025 | E18: 3382.36 | F18: 30 | G18: =E18/30 -> 112.74533 | H18: =E18*F18/30 -> 3382.36 | I18: 600 | O18: =G18/8*1.5*K18+G18/8*L18*2+G18/8*2.5*M18 -> 0 | P18: 5000 | Q18: =H18+I18+J18+O18+P18+N18 -> 8982.36 | R18: =H18+J18+O18+P18 -> 8382.36 | S18: =IF(R18<=2000,0,IF(R18<=4000,R18*0.15-300,IF(R18<=7000,R18*0.2-500,IF(R18<=10000,R18*0.25-850,IF(R18<=14000,R18*0.3-1350,IF(R18>=14001,R18*0.35-2050)))))) -> 1245.59 | U18: =+H18*0.07 -> 236.7652 | V18: =+H18*0.11 -> 372.0596 | W18: =+S18+T18+U18 -> 1482.3552 | X18: =+Q18-W18 -> 7500.0048
A19: 14 | B19: Amare Desalew | D19: 7\8\2025 | E19: 6712.33 | F19: 30 | G19: =E19/30 -> 223.74433 | H19: =E19*F19/30 -> 6712.33 | I19: 600 | O19: =G19/8*1.5*K19+G19/8*L19*2+G19/8*2.5*M19 -> 0 | Q19: =H19+I19+J19+O19+P19+N19 -> 7312.33 | R19: =H19+J19+O19+P19 -> 6712.33 | S19: =IF(R19<=2000,0,IF(R19<=4000,R19*0.15-300,IF(R19<=7000,R19*0.2-500,IF(R19<=10000,R19*0.25-850,IF(R19<=14000,R19*0.3-1350,IF(R19>=14001,R19*0.35-2050)))))) -> 842.466 | U19: =+H19*0.07 -> 469.8631 | V19: =+H19*0.11 -> 738.3563 | W19: =+S19+T19+U19 -> 1312.3291 | X19: =+Q19-W19 -> 6000.0009
A20: 15 | B20: Abeya Taye | D20: 7\8\2025 | E20: 6712.33 | F20: 30 | G20: =E20/30 -> 223.74433 | H20: =E20*F20/30 -> 6712.33 | I20: 600 | O20: =G20/8*1.5*K20+G20/8*L20*2+G20/8*2.5*M20 -> 0 | Q20: =H20+I20+J20+O20+P20+N20 -> 7312.33 | R20: =H20+J20+O20+P20 -> 6712.33 | S20: =IF(R20<=2000,0,IF(R20<=4000,R20*0.15-300,IF(R20<=7000,R20*0.2-500,IF(R20<=10000,R20*0.25-850,IF(R20<=14000,R20*0.3-1350,IF(R20>=14001,R20*0.35-2050)))))) -> 842.466 | U20: =+H20*0.07 -> 469.8631 | V20: =+H20*0.11 -> 738.3563 | W20: =+S20+T20+U20 -> 1312.3291 | X20: =+Q20-W20 -> 6000.0009
A21: 16 | B21: Ermias Tafesse | D21: 7\8\2025 | E21: 5342.47 | F21: 30 | G21: =E21/30 -> 178.08233 | H21: =E21*F21/30 -> 5342.47 | I21: 600 | O21: =G21/8*1.5*K21+G21/8*L21*2+G21/8*2.5*M21 -> 0 | Q21: =H21+I21+J21+O21+P21+N21 -> 5942.47 | R21: =H21+J21+O21+P21 -> 5342.47 | S21: =IF(R21<=2000,0,IF(R21<=4000,R21*0.15-300,IF(R21<=7000,R21*0.2-500,IF(R21<=10000,R21*0.25-850,IF(R21<=14000,R21*0.3-1350,IF(R21>=14001,R21*0.35-2050)))))) -> 568.494 | U21: =+H21*0.07 -> 373.9729 | V21: =+H21*0.11 -> 587.6717 | W21: =+S21+T21+U21 -> 942.4669 | X21: =+Q21-W21 -> 5000.0031
A22: 17 | B22: Wondesen Abera | D22: 7\8\2025 | E22: 5342.47 | F22: 30 | G22: =E22/30 -> 178.08233 | H22: =E22*F22/30 -> 5342.47 | I22: 600 | O22: =G22/8*1.5*K22+G22/8*L22*2+G22/8*2.5*M22 -> 0 | Q22: =H22+I22+J22+O22+P22+N22 -> 5942.47 | R22: =H22+J22+O22+P22 -> 5342.47 | S22: =IF(R22<=2000,0,IF(R22<=4000,R22*0.15-300,IF(R22<=7000,R22*0.2-500,IF(R22<=10000,R22*0.25-850,IF(R22<=14000,R22*0.3-1350,IF(R22>=14001,R22*0.35-2050)))))) -> 568.494 | U22: =+H22*0.07 -> 373.9729 | V22: =+H22*0.11 -> 587.6717 | W22: =+S22+T22+U22 -> 942.4669 | X22: =+Q22-W22 -> 5000.0031
A23: 18 | B23: Hailemichael Agaze | D23: 7\8\2025 | E23: 5342.47 | F23: 30 | G23: =E23/30 -> 178.08233 | H23: =E23*F23/30 -> 5342.47 | I23: 600 | O23: =G23/8*1.5*K23+G23/8*L23*2+G23/8*2.5*M23 -> 0 | Q23: =H23+I23+J23+O23+P23+N23 -> 5942.47 | R23: =H23+J23+O23+P23 -> 5342.47 | S23: =IF(R23<=2000,0,IF(R23<=4000,R23*0.15-300,IF(R23<=7000,R23*0.2-500,IF(R23<=10000,R23*0.25-850,IF(R23<=14000,R23*0.3-1350,IF(R23>=14001,R23*0.35-2050)))))) -> 568.494 | U23: =+H23*0.07 -> 373.9729 | V23: =+H23*0.11 -> 587.6717 | W23: =+S23+T23+U23 -> 942.4669 | X23: =+Q23-W23 -> 5000.0031
A24: 19 | B24: Seid Mohammed | D24: 7\8\2025 | E24: 6712.33 | F24: 30 | G24: =E24/30 -> 223.74433 | H24: =E24*F24/30 -> 6712.33 | I24: 600 | O24: =G24/8*1.5*K24+G24/8*L24*2+G24/8*2.5*M24 -> 0 | Q24: =H24+I24+J24+O24+P24+N24 -> 7312.33 | R24: =H24+J24+O24+P24 -> 6712.33 | S24: =IF(R24<=2000,0,IF(R24<=4000,R24*0.15-300,IF(R24<=7000,R24*0.2-500,IF(R24<=10000,R24*0.25-850,IF(R24<=14000,R24*0.3-1350,IF(R24>=14001,R24*0.35-2050)))))) -> 842.466 | U24: =+H24*0.07 -> 469.8631 | V24: =+H24*0.11 -> 738.3563 | W24: =+S24+T24+U24 -> 1312.3291 | X24: =+Q24-W24 -> 6000.0009
A25: 20 | B25: Yoseph Tamirat | D25: 7\8\2025 | E25: 6712.33 | F25: 30 | G25: =E25/30 -> 223.74433 | H25: =E25*F25/30 -> 6712.33 | I25: 600 | O25: =G25/8*1.5*K25+G25/8*L25*2+G25/8*2.5*M25 -> 0 | Q25: =H25+I25+J25+O25+P25+N25 -> 7312.33 | R25: =H25+J25+O25+P25 -> 6712.33 | S25: =IF(R25<=2000,0,IF(R25<=4000,R25*0.15-300,IF(R25<=7000,R25*0.2-500,IF(R25<=10000,R25*0.25-850,IF(R25<=14000,R25*0.3-1350,IF(R25>=14001,R25*0.35-2050)))))) -> 842.466 | U25: =+H25*0.07 -> 469.8631 | V25: =+H25*0.11 -> 738.3563 | W25: =+S25+T25+U25 -> 1312.3291 | X25: =+Q25-W25 -> 6000.0009
A26: 21 | B26: Ermias Zewdu | D26: 7\8\2025 | E26: 6712.33 | F26: 30 | G26: =E26/30 -> 223.74433 | H26: =E26*F26/30 -> 6712.33 | I26: 600 | O26: =G26/8*1.5*K26+G26/8*L26*2+G26/8*2.5*M26 -> 0 | Q26: =H26+I26+J26+O26+P26+N26 -> 7312.33 | R26: =H26+J26+O26+P26 -> 6712.33 | S26: =IF(R26<=2000,0,IF(R26<=4000,R26*0.15-300,IF(R26<=7000,R26*0.2-500,IF(R26<=10000,R26*0.25-850,IF(R26<=14000,R26*0.3-1350,IF(R26>=14001,R26*0.35-2050)))))) -> 842.466 | U26: =+H26*0.07 -> 469.8631 | V26: =+H26*0.11 -> 738.3563 | W26: =+S26+T26+U26 -> 1312.3291 | X26: =+Q26-W26 -> 6000.0009
A27: 22 | B27: Mekdes G\michael | D27: 7\8\2025 | E27: 4520.55 | F27: 30 | G27: =E27/30 -> 150.685 | H27: =E27*F27/30 -> 4520.55 | I27: 600 | O27: =G27/8*1.5*K27+G27/8*L27*2+G27/8*2.5*M27 -> 0 | P27: 2000 | Q27: =H27+I27+J27+O27+P27+N27 -> 7120.55 | R27: =H27+J27+O27+P27 -> 6520.55 | S27: =IF(R27<=2000,0,IF(R27<=4000,R27*0.15-300,IF(R27<=7000,R27*0.2-500,IF(R27<=10000,R27*0.25-850,IF(R27<=14000,R27*0.3-1350,IF(R27>=14001,R27*0.35-2050)))))) -> 804.11 | U27: =+H27*0.07 -> 316.4385 | V27: =+H27*0.11 -> 497.2605 | W27: =+S27+T27+U27 -> 1120.5485 | X27: =+Q27-W27 -> 6000.0015
A28: 23 | B28: Andualem Yitna | D28: 7\8\2025 | E28: 6712.33 | F28: 30 | G28: =E28/30 -> 223.74433 | H28: =E28*F28/30 -> 6712.33 | I28: 600 | O28: =G28/8*1.5*K28+G28/8*L28*2+G28/8*2.5*M28 -> 0 | Q28: =H28+I28+J28+O28+P28+N28 -> 7312.33 | R28: =H28+J28+O28+P28 -> 6712.33 | S28: =IF(R28<=2000,0,IF(R28<=4000,R28*0.15-300,IF(R28<=7000,R28*0.2-500,IF(R28<=10000,R28*0.25-850,IF(R28<=14000,R28*0.3-1350,IF(R28>=14001,R28*0.35-2050)))))) -> 842.466 | U28: =+H28*0.07 -> 469.8631 | V28: =+H28*0.11 -> 738.3563 | W28: =+S28+T28+U28 -> 1312.3291 | X28: =+Q28-W28 -> 6000.0009
A29: 24 | B29: Mahlet Meseret | D29: 7\8\2025 | E29: 5955.88 | F29: 30 | G29: =E29/30 -> 198.52933 | H29: =E29*F29/30 -> 5955.88 | I29: 600 | O29: =G29/8*1.5*K29+G29/8*L29*2+G29/8*2.5*M29 -> 0 | P29: 2000 | Q29: =H29+I29+J29+O29+P29+N29 -> 8555.88 | R29: =H29+J29+O29+P29 -> 7955.88 | S29: =IF(R29<=2000,0,IF(R29<=4000,R29*0.15-300,IF(R29<=7000,R29*0.2-500,IF(R29<=10000,R29*0.25-850,IF(R29<=14000,R29*0.3-1350,IF(R29>=14001,R29*0.35-2050)))))) -> 1138.97 | U29: =+H29*0.07 -> 416.9116 | V29: =+H29*0.11 -> 655.1468 | W29: =+S29+T29+U29 -> 1555.8816 | X29: =+Q29-W29 -> 6999.9984
A30: 25 | B30: Abnet Biru | D30: 8\7\2025 | E30: 6713 | F30: 30 | G30: =E30/30 -> 223.76667 | H30: =E30*F30/30 -> 6713 | I30: 600 | O30: =G30/8*1.5*K30+G30/8*L30*2+G30/8*2.5*M30 -> 0 | Q30: =H30+I30+J30+O30+P30+N30 -> 7313 | R30: =H30+J30+O30+P30 -> 6713 | S30: =IF(R30<=2000,0,IF(R30<=4000,R30*0.15-300,IF(R30<=7000,R30*0.2-500,IF(R30<=10000,R30*0.25-850,IF(R30<=14000,R30*0.3-1350,IF(R30>=14001,R30*0.35-2050)))))) -> 842.6 | U30: =+H30*0.07 -> 469.91 | V30: =+H30*0.11 -> 738.43 | W30: =+S30+T30+U30 -> 1312.51 | X30: =+Q30-W30 -> 6000.49
A31: 26 | B31: Amanuel Tamru | D31: 8\7\2025 | E31: 851.61 | F31: 30 | G31: =E31/30 -> 28.387 | H31: =E31*F31/30 -> 851.61 | I31: 600 | O31: =G31/8*1.5*K31+G31/8*L31*2+G31/8*2.5*M31 -> 0 | Q31: =H31+I31+J31+O31+P31+N31 -> 1451.61 | R31: =H31+J31+O31+P31 -> 851.61 | S31: =IF(R31<=2000,0,IF(R31<=4000,R31*0.15-300,IF(R31<=7000,R31*0.2-500,IF(R31<=10000,R31*0.25-850,IF(R31<=14000,R31*0.3-1350,IF(R31>=14001,R31*0.35-2050)))))) -> 0 | U31: =+H31*0.07 -> 59.6127 | V31: =+H31*0.11 -> 93.6771 | W31: =+S31+T31+U31 -> 59.6127 | X31: =+Q31-W31 -> 1391.9973
A32: 27 | B32: Fekadu Taye | D32: 7\8\2025 | E32: 6712.33 | F32: 30 | G32: =E32/30 -> 223.74433 | H32: =E32*F32/30 -> 6712.33 | I32: 600 | O32: =G32/8*1.5*K32+G32/8*L32*2+G32/8*2.5*M32 -> 0 | Q32: =H32+I32+J32+O32+P32+N32 -> 7312.33 | R32: =H32+J32+O32+P32 -> 6712.33 | S32: =IF(R32<=2000,0,IF(R32<=4000,R32*0.15-300,IF(R32<=7000,R32*0.2-500,IF(R32<=10000,R32*0.25-850,IF(R32<=14000,R32*0.3-1350,IF(R32>=14001,R32*0.35-2050)))))) -> 842.466 | U32: =+H32*0.07 -> 469.8631 | V32: =+H32*0.11 -> 738.3563 | W32: =+S32+T32+U32 -> 1312.3291 | X32: =+Q32-W32 -> 6000.0009
A33: 28 | B33: Amanuel Birhanu | D33: 8\7\2025 | E33: 7739.71 | F33: 30 | G33: =E33/30 -> 257.99033 | H33: =E33*F33/30 -> 7739.71 | I33: 600 | O33: =G33/8*1.5*K33+G33/8*L33*2+G33/8*2.5*M33 -> 0 | Q33: =H33+I33+J33+O33+P33+N33 -> 8339.71 | R33: =H33+J33+O33+P33 -> 7739.71 | S33: =IF(R33<=2000,0,IF(R33<=4000,R33*0.15-300,IF(R33<=7000,R33*0.2-500,IF(R33<=10000,R33*0.25-850,IF(R33<=14000,R33*0.3-1350,IF(R33>=14001,R33*0.35-2050)))))) -> 1084.9275 | U33: =+H33*0.07 -> 541.7797 | V33: =+H33*0.11 -> 851.3681 | W33: =+S33+T33+U33 -> 1626.7072 | X33: =+Q33-W33 -> 6713.0028
A34: 29 | B34: Frewoin Molla | D34: 11\9\2025 | E34: 29913.8 | F34: 30 | G34: =E34/30 -> 997.12667 | H34: =E34*F34/30 -> 29913.8 | I34: 600 | O34: =G34/8*1.5*K34+G34/8*L34*2+G34/8*2.5*M34 -> 0 | Q34: =H34+I34+J34+O34+P34+N34 -> 30513.8 | R34: =H34+J34+O34+P34 -> 29913.8 | S34: =IF(R34<=2000,0,IF(R34<=4000,R34*0.15-300,IF(R34<=7000,R34*0.2-500,IF(R34<=10000,R34*0.25-850,IF(R34<=14000,R34*0.3-1350,IF(R34>=14001,R34*0.35-2050)))))) -> 8419.83 | U34: =+H34*0.07 -> 2093.966 | V34: =+H34*0.11 -> 3290.518 | W34: =+S34+T34+U34 -> 10513.796 | X34: =+Q34-W34 -> 20000.004
A35: 30 | B35: Emanuel Alem | D35: 11\9\2025 | E35: 12777.78 | F35: 30 | G35: =E35/30 -> 425.926 | H35: =E35*F35/30 -> 12777.78 | I35: 600 | O35: =G35/8*1.5*K35+G35/8*L35*2+G35/8*2.5*M35 -> 0 | Q35: =H35+I35+J35+O35+P35+N35 -> 13377.78 | R35: =H35+J35+O35+P35 -> 12777.78 | S35: =IF(R35<=2000,0,IF(R35<=4000,R35*0.15-300,IF(R35<=7000,R35*0.2-500,IF(R35<=10000,R35*0.25-850,IF(R35<=14000,R35*0.3-1350,IF(R35>=14001,R35*0.35-2050)))))) -> 2483.334 | U35: =+H35*0.07 -> 894.4446 | V35: =+H35*0.11 -> 1405.5558 | W35: =+S35+T35+U35 -> 3377.7786 | X35: =+Q35-W35 -> 10000.001
A36: 31 | B36: Mulualem Abayneh | D36: 11\9\2025 | E36: 4657.54 | F36: 30 | G36: =E36/30 -> 155.25133 | H36: =E36*F36/30 -> 4657.54 | I36: 600 | O36: =G36/8*1.5*K36+G36/8*L36*2+G36/8*2.5*M36 -> 0 | Q36: =H36+I36+J36+O36+P36+N36 -> 5257.54 | R36: =H36+J36+O36+P36 -> 4657.54 | S36: =IF(R36<=2000,0,IF(R36<=4000,R36*0.15-300,IF(R36<=7000,R36*0.2-500,IF(R36<=10000,R36*0.25-850,IF(R36<=14000,R36*0.3-1350,IF(R36>=14001,R36*0.35-2050)))))) -> 431.508 | U36: =+H36*0.07 -> 326.0278 | V36: =+H36*0.11 -> 512.3294 | W36: =+S36+T36+U36 -> 757.5358 | X36: =+Q36-W36 -> 4500.0042
A37: 32 | B37: Gizaw Alfoaychew | D37: 11\9\2025 | E37: 6027.4 | F37: 30 | G37: =E37/30 -> 200.91333 | H37: =E37*F37/30 -> 6027.4 | I37: 600 | O37: =G37/8*1.5*K37+G37/8*L37*2+G37/8*2.5*M37 -> 0 | Q37: =H37+I37+J37+O37+P37+N37 -> 6627.4 | R37: =H37+J37+O37+P37 -> 6027.4 | S37: =IF(R37<=2000,0,IF(R37<=4000,R37*0.15-300,IF(R37<=7000,R37*0.2-500,IF(R37<=10000,R37*0.25-850,IF(R37<=14000,R37*0.3-1350,IF(R37>=14001,R37*0.35-2050)))))) -> 705.48 | U37: =+H37*0.07 -> 421.918 | V37: =+H37*0.11 -> 663.014 | W37: =+S37+T37+U37 -> 1127.398 | X37: =+Q37-W37 -> 5500.002
A38: 33 | B38: Amanuel Kifleyaekob | D38: 11\9\2025 | E38: 6712.33 | F38: 30 | G38: =E38/30 -> 223.74433 | H38: =E38*F38/30 -> 6712.33 | I38: 600 | O38: =G38/8*1.5*K38+G38/8*L38*2+G38/8*2.5*M38 -> 0 | Q38: =H38+I38+J38+O38+P38+N38 -> 7312.33 | R38: =H38+J38+O38+P38 -> 6712.33 | S38: =IF(R38<=2000,0,IF(R38<=4000,R38*0.15-300,IF(R38<=7000,R38*0.2-500,IF(R38<=10000,R38*0.25-850,IF(R38<=14000,R38*0.3-1350,IF(R38>=14001,R38*0.35-2050)))))) -> 842.466 | U38: =+H38*0.07 -> 469.8631 | V38: =+H38*0.11 -> 738.3563 | W38: =+S38+T38+U38 -> 1312.3291 | X38: =+Q38-W38 -> 6000.0009
A39: 34 | B39: Yabsira Shiferaw | D39: 11\9\2025 | E39: 6734.25 | F39: 30 | G39: =E39/30 -> 224.475 | H39: =E39*F39/30 -> 6734.25 | I39: 600 | O39: =G39/8*1.5*K39+G39/8*L39*2+G39/8*2.5*M39 -> 0 | Q39: =H39+I39+J39+O39+P39+N39 -> 7334.25 | R39: =H39+J39+O39+P39 -> 6734.25 | S39: =IF(R39<=2000,0,IF(R39<=4000,R39*0.15-300,IF(R39<=7000,R39*0.2-500,IF(R39<=10000,R39*0.25-850,IF(R39<=14000,R39*0.3-1350,IF(R39>=14001,R39*0.35-2050)))))) -> 846.85 | U39: =+H39*0.07 -> 471.3975 | V39: =+H39*0.11 -> 740.7675 | W39: =+S39+T39+U39 -> 1318.2475 | X39: =+Q39-W39 -> 6016.0025
A40: 35 | B40: Dawit Semere | D40: 11\9\2025 | E40: 7647.06 | F40: 30 | G40: =E40/30 -> 254.902 | H40: =E40*F40/30 -> 7647.06 | I40: 600 | O40: =G40/8*1.5*K40+G40/8*L40*2+G40/8*2.5*M40 -> 0 | Q40: =H40+I40+J40+O40+P40+N40 -> 8247.06 | R40: =H40+J40+O40+P40 -> 7647.06 | S40: =IF(R40<=2000,0,IF(R40<=4000,R40*0.15-300,IF(R40<=7000,R40*0.2-500,IF(R40<=10000,R40*0.25-850,IF(R40<=14000,R40*0.3-1350,IF(R40>=14001,R40*0.35-2050)))))) -> 1061.765 | U40: =+H40*0.07 -> 535.2942 | V40: =+H40*0.11 -> 841.1766 | W40: =+S40+T40+U40 -> 1597.0592 | X40: =+Q40-W40 -> 6650.0008
...

Sheet at bank AUGEST
A1: TEWOS TRADING PLC
A2: THE MONTH OF AUGEST 2025 G.C
A3: NO | B3: EMPLOYEE NAME | C3: NET PAY | D3: ACCOUNT NUMBER
A4: 1 | B4: Tewodros Atnafu | C4: =+'Augest 2025'!X6 -> 12700.02 | D4: 0193858126011
A5: =+A4+1 -> 2 | B5: Selam T\haimanote | C5: =+'Augest 2025'!X7 -> 12700.02 | D5: 0105123164011
A6: =+A5+1 -> 3 | B6: Samrawit Atnafu | C6: =+'Augest 2025'!X8 -> 13621.28 | D6: 5070789450011
A7: =+A6+1 -> 4 | B7: Amanuel Beyene | C7: =+'Augest 2025'!X9 -> 13621.28 | D7: 5070795922011
A8: =+A7+1 -> 5 | B8: Melkie Kindie | C8: =+'Augest 2025'!X10 -> 13621.28 | D8: 5070795927011
A9: =+A8+1 -> 6 | B9: Tekalegne Defar | C9: =+'Augest 2025'!X11 -> 31896.5 | D9: 5070795930011
A10: =+A9+1 -> 7 | B10: Solomon Kassahun | C10: =+'Augest 2025'!X12 -> 22241.402 | D10: 5070795926011
A11: =+A10+1 -> 8 | B11: Amanuel Almayehu | C11: =+'Augest 2025'!X13 -> 10230.197 | D11: 5070795954011
A12: =+A11+1 -> 9 | B12: Derbew Ayelegne | C12: =+'Augest 2025'!X14 -> 4697.513 | D12: 5782444595011
A13: =+A12+1 -> 10 | B13: Demeke Getachew | C13: =+'Augest 2025'!X15 -> 4697.513 | D13: 5893914931011
A14: =+A13+1 -> 11 | B14: Sewunet Alemu | C14: =+'Augest 2025'!X16 -> 2894.3508 | D14: 5099874030011
A15: =+A14+1 -> 12 | B15: Yordanos Demirew | C15: =+'Augest 2025'!X17 -> 6999.9984 | D15: 5099871851011
A16: =+A15+1 -> 13 | B16: Awoke Guade | C16: =+'Augest 2025'!X18 -> 7500.0048 | D16: 5070795931011
... A43: =+A42+1 -> 40 | B43: Mahlet Tegegn | C43: =+'Augest 2025'!X45 -> 4666.999 | D43: 5008211559011
A44: 41 | B44: Betelhem Getachaw | C44: =+'Augest 2025'!X46 -> 10000.001
A45: TOTAL | C45: =SUM(C4:C44) -> 334459.88
